import * as is from '@redux-saga/is'
import { CANCEL, IO, TASK_CANCEL } from '@redux-saga/symbols'
import newTask from './newTask'
import effectRunnerMap from './effectRunnerMap'
import { noop, uid as nextEffectId, shouldCancel, shouldTerminate, asyncIteratorSymbol } from './utils'

export default function proc(env, iterator, parentContext, parentEffectId, meta, isRoot, cont) {
  if (process.env.NODE_ENV !== 'production' && iterator[asyncIteratorSymbol]) {
    throw new Error("redux-saga doesn't support async generators, please use only regular ones")
  }
  const finalRunEffect = env.finalizeRunEffect(runEffect)
  // some basic runners that will be passed to the specific effect-runner
  const runners = { digestEffect, resolvePromise, resolveIterator }

  /**
    Tracks the current effect cancellation
    Each time the generator progresses. calling runEffect will set a new value
    on it. It allows propagating cancellation to child effects
  **/
  next.cancel = noop

  /** Create a main task to track the main flow */
  const mainTask = { meta, cancel: cancelMain, running: true, cancelled: false }

  /**
    Creates a new task descriptor for this generator.
    A task is the aggregation of it's mainTask and all it's forked tasks.
  **/
  const task = newTask(env, mainTask, parentContext, parentEffectId, meta, isRoot, cont)

  /**
    attaches cancellation logic to this task's continuation
    this will permit cancellation to propagate down the call chain
  **/
  cont.cancel = task.cancel

  // kicks up the generator
  next()

  // then return the task descriptor to the caller
  return task

  /** cancellation of the main task. We'll simply resume the Generator with TASK_CANCEL */
  function cancelMain() {
    if (mainTask.running && !mainTask.cancelled) {
      mainTask.cancelled = true
      next(TASK_CANCEL)
    }
  }

  /**
    This is the generator driver
    It's a recursive async/continuation function which calls itself
    until the generator terminates or throws
  **/
  function next(arg, isErr) {
    // Preventive measure. If we end up here, then there is really something wrong
    if (!mainTask.running) {
      throw new Error('Trying to resume an already finished generator')
    }

    try {
      let result
      if (isErr) {
        result = iterator.throw(arg)
      } else if (shouldCancel(arg)) {
        /**
          getting TASK_CANCEL automatically cancels the main task
          We can get this value here

          - By cancelling the parent task manually
          - By joining a Cancelled task
        **/
        mainTask.cancelled = true
        /**
          Cancels the current effect; this will propagate the cancellation down to any called tasks
        **/
        next.cancel()
        /**
          If this Generator has a `return` method then invokes it
          This will jump to the finally block
        **/
        result = is.func(iterator.return) ? iterator.return(TASK_CANCEL) : { done: true, value: TASK_CANCEL }
      } else if (shouldTerminate(arg)) {
        // We get TERMINATE flag, i.e. by taking from a channel that ended using `take` (and not `takem` used to trap End of channels)
        result = is.func(iterator.return) ? iterator.return() : { done: true }
      } else {
        result = iterator.next(arg)
      }

      if (!result.done) {
        digestEffect(result.value, parentEffectId, '', next)
      } else {
        /**
          This Generator has ended, terminate the main task and notify the fork queue
        **/
        mainTask.running = false
        mainTask.cont(result.value)
      }
    } catch (error) {
      if (mainTask.cancelled) {
        env.logError(error)
      }
      mainTask.running = false
      mainTask.cont(error, true)
    }
  }

  function runEffect(effect, effectId, currCb) {
    /**
      each effect runner must attach its own logic of cancellation to the provided callback
      it allows this generator to propagate cancellation downward.

      ATTENTION! effect runners must setup the cancel logic by setting cb.cancel = [cancelMethod]
      And the setup must occur before calling the callback

      This is a sort of inversion of control: called async functions are responsible
      of completing the flow by calling the provided continuation; while caller functions
      are responsible for aborting the current flow by calling the attached cancel function

      Library users can attach their own cancellation logic to promises by defining a
      promise[CANCEL] method in their returned promises
      ATTENTION! calling cancel must have no effect on an already completed or cancelled effect
    **/
    if (is.promise(effect)) {
      resolvePromise(effect, currCb)
    } else if (is.iterator(effect)) {
      resolveIterator(effect, effectId, meta, currCb)
    } else if (effect && effect[IO]) {
      const effectRunner = effectRunnerMap[effect.type]
      effectRunner(env, effect.payload, currCb, task, effectId, runners)
    } else {
      // anything else returned as is
      currCb(effect)
    }
  }

  function digestEffect(effect, parentEffectId, label = '', cb) {
    const effectId = nextEffectId()
    env.sagaMonitor && env.sagaMonitor.effectTriggered({ effectId, parentEffectId, label, effect })

    /**
      completion callback and cancel callback are mutually exclusive
      We can't cancel an already completed effect
      And We can't complete an already cancelled effectId
    **/
    let effectSettled

    // Completion callback passed to the appropriate effect runner
    function currCb(res, isErr) {
      if (effectSettled) {
        return
      }

      effectSettled = true
      cb.cancel = noop // defensive measure
      if (env.sagaMonitor) {
        if (isErr) {
          env.sagaMonitor.effectRejected(effectId, res)
        } else {
          env.sagaMonitor.effectResolved(effectId, res)
        }
      }
      if (isErr) {
        task.crashedEffect = effect
      }
      cb(res, isErr)
    }
    // tracks down the current cancel
    currCb.cancel = noop

    // setup cancellation logic on the parent cb
    cb.cancel = () => {
      // prevents cancelling an already completed effect
      if (effectSettled) {
        return
      }

      effectSettled = true
      /**
        propagates cancel downward
        catch uncaught cancellations errors; since we can no longer call the completion
        callback, log errors raised during cancellations into the console
      **/
      try {
        currCb.cancel()
      } catch (err) {
        env.logError(err)
      }
      currCb.cancel = noop // defensive measure

      env.sagaMonitor && env.sagaMonitor.effectCancelled(effectId)
    }

    finalRunEffect(effect, effectId, currCb)
  }

  function resolvePromise(promise, cb) {
    const cancelPromise = promise[CANCEL]
    if (is.func(cancelPromise)) {
      cb.cancel = cancelPromise
    } else if (is.func(promise.abort)) {
      cb.cancel = () => promise.abort()
    }
    promise.then(cb, error => cb(error, true))
  }

  function resolveIterator(iterator, effectId, meta, cb) {
    proc(env, iterator, task.context, effectId, meta, /* isRoot */ false, cb)
  }
}
